Workbook

Sheet CONTRIBUTIONS
A1: DATE | B1: AMMOUNT | C1: Notes
A2: 46170 | B2: 33738.31 | C2: seed

Sheet CASH_FLOW
A1: ACCOUNT | B1: CASH_BALANCE | C1: ASSET_COST_GBP | D1: ASSET_VALUE_GBP | E1: Total
A2: cash | B2: 20000 | C2: 11.84 | D2: 19.6548 | E2: 27.8148 | G2: Unreal_Profit/loss | H2: 6833.0348 | I2: 0.31723938
A3: target_cash_reserve | B3: 12000 | C3: 21527.21 | D3: 28153.17 | E3: 28344.27 | G3: AVAILABLE | H3: 12199.26
A4: emergency_reserve | B4: 12000 | G4: Portfolio_Value | H4: =+E5 -> 28372.085
A5: cash_contributions | B5: 21539.08 | C5: 21539.05 | D5: 28172.825 | E5: 28372.085 | G5: Real_Profit/loss | H5: ? | I5: ?
A6: max_deployment_percent | B6: 70
D7: =+C5/D9 -> 0.64220754 | G7: Net_Value | H7: =+H4+H3 -> 40571.345
A9: IKBR | B9: 8.16 | C9: =SUM(B7:B7) -> 0 | D9: =+B5+B4 -> 33539.08
A10: IWEB | B10: 191.1
A11: HOLDING | B11: 10000 | F11: cash: 0
B12: =SUM(B9:B11) -> 10199.26 | C12: =SUM(C2:C3) -> 21539.05 | F12: target_cash_reserve: 12000
C13: =SUM(B7:B7) -> 0 | D13: =+SUM(C12:C13) -> 21539.05 | E13: =+C5/D13 -> 1 | F13: emergency_reserve: 20000
F14: cash_contributions: 33738.31
F15: max_deployment_percent: 70

Sheet INPUT_TRANSACTIONS
A1: trade_date | B1: account | C1: symbol | D1: action | E1: quantity | F1: trade_currency | G1: trade_price | H1: fees | I1: fx_rate_to_gbp | J1: notes
A2: 45716 | B2: IWEB | C2: META | D2: BUY | E2: 6 | F2: USD | G2: 655.37891 | H2: 47.51 | I2: =1/1.2413 -> 0.80560702
A3: 45716 | B3: IWEB | C3: HOOD | D3: BUY | E3: 44 | F3: USD | G3: 48.313999 | H3: 25.65 | I3: =1/1.2421 -> 0.80508816
A4: 45859 | B4: IWEB | C4: NVDA | D4: BUY | E4: 18 | F4: USD | G4: 172.2892 | H4: 34.91 | I4: =1/1.3296 -> 0.7521059
A5: 46059 | B5: IWEB | C5: AMD | D5: BUY | E5: 12 | F5: USD | G5: 207.6904 | H5: 27.87 | I5: =1/1.3403 -> 0.74610162 | J5: =+G5*E5*I5+H5 -> 1887.3677
A6: 46059 | B6: IWEB | C6: CRWV | D6: BUY | E6: 31 | F6: USD | G6: 89.7276 | H6: 31.08 | I6: =1/1.3411 -> 0.74565655
A7: 46059 | B7: IWEB | C7: HOOD | D7: BUY | E7: 31 | F7: USD | G7: 83.737099 | H7: 29.02 | I7: =1/1.3046 -> 0.76651847
A8: 46108 | B8: IWEB | C8: TSLA | D8: BUY | E8: 11 | F8: USD | G8: 360.39499 | H8: 45.5 | I8: =1/1.3068 -> 0.76522804
A9: 46119 | B9: IWEB | C9: TSLA | D9: BUY | E9: 7 | F9: USD | G9: 339.65561 | H9: 27.33 | I9: =1/1.3059 -> 0.76575542
A10: 46125 | B10: IWEB | C10: LWLG | D10: BUY | E10: 80 | F10: USD | G10: 11.7038 | H10: 8.19 | I10: =1/1.3275 -> 0.75329567
A11: 46125 | B11: IWEB | C11: LWLG | D11: BUY | E11: 44 | F11: USD | G11: 11.7038 | H11: 8.19 | I11: =1/1.3275 -> 0.75329567
A12: 46125 | B12: IWEB | C12: POET | D12: BUY | E12: 444 | F12: USD | G12: 7.4671001 | H12: 37.45 | I12: =1/1.3272 -> 0.75346594
A13: 46139 | B13: IBKR | C13: POET | D13: BUY | E13: 2 | F13: USD | G13: 7.93 | H13: 0.12 | I13: =1/1.353 -> 0.7390983
E16: =+E5*G5*I5 -> 1859.4977

Sheet PORTFOLIO_HISTORY
A1: snapshot_date | B1: portfolio_value | C1: invested_value | D1: cash | E1: cash_contributions | F1: capital_status | G1: cash_funding_ratio

Sheet watchlist
A1: symbol | B1: StockName | C1: LastTradeTime | D1: TradeCurrency | E1: StockPrice | F1: ChangePercent | G1: Change | H1: P/E | I1: Beta | J1: 52WkHigh | K1: 52WkLow | L1: DayHigh | M1: DayLow | N1: Open | O1: PreviousClose | P1: Volume | Q1: AverageVolume | R1: YearIncorported | S1: Employees | T1: Industry | U1: MarketCap | V1: SharesOutstanding | W1: 50SMA | X1: 100SMA | Y1: 150SMA | Z1: 200SMA | AA1: EMA | AB1: RSI | AC1: MACD | AD1: UpperBB | AE1: LowerBB
A2: AAOI | B2: #VALUE! | C2: {=_FV(B2,"Last trade time",TRUE)} -> 46182.798 | D2: {=_FV(B2,"Currency")} -> USD | E2: {=_FV(B2,"Price")} -> 167.33 | F2: {=_FV(B2,"Change (%)",TRUE)} -> -0.149054 | G2: {=_FV(B2,"Change")} -> -29.31 | H2: {=_FV(B2,"P/E",TRUE)} -> 0 | I2: {=_FV(B2,"Beta")} -> 3.6016 | J2: {=_FV(B2,"52 week high",TRUE)} -> 233.67 | K2: {=_FV(B2,"52 week low",TRUE)} -> 15.29 | L2: {=_FV(B2,"High")} -> 207.6 | M2: {=_FV(B2,"Low")} -> 160.87 | N2: {=_FV(B2,"Open")} -> 203.49 | O2: {=_FV(B2,"Previous close",TRUE)} -> 196.64 | P2: {=_FV(B2,"Volume")} -> 21509564 | Q2: {=_FV(B2,"Volume average",TRUE)} -> 12730889 | R2: {=_FV(B2,"Year incorporated",TRUE)} -> 2013 | S2: {=_FV(B2,"Employees")} -> 4691 | T2: {=_FV(B2,"Industry")} -> Electronic Equipment & Parts | U2: {=_FV(B2,"Market cap",TRUE)} -> 13427022704 | V2: {=_FV(B2,"Shares outstanding",TRUE)} -> 80242770
A3: AAPL | B3: #VALUE! | C3: {=_FV(B3,"Last trade time",TRUE)} -> 46182.798 | D3: {=_FV(B3,"Currency")} -> USD | E3: {=_FV(B3,"Price")} -> 291.74 | F3: {=_FV(B3,"Change (%)",TRUE)} -> -0.0325 | G3: {=_FV(B3,"Change")} -> -9.8 | H3: {=_FV(B3,"P/E",TRUE)} -> 35.432 | I3: {=_FV(B3,"Beta")} -> 1.0887 | J3: {=_FV(B3,"52 week high",TRUE)} -> 317.4 | K3: {=_FV(B3,"52 week low",TRUE)} -> 195.07 | L3: {=_FV(B3,"High")} -> 300.72 | M3: {=_FV(B3,"Low")} -> 287.78 | N3: {=_FV(B3,"Open")} -> 300 | O3: {=_FV(B3,"Previous close",TRUE)} -> 301.54 | P3: {=_FV(B3,"Volume")} -> 49794495 | Q3: {=_FV(B3,"Volume average",TRUE)} -> 49348841 | R3: {=_FV(B3,"Year incorporated",TRUE)} -> 1977 | S3: {=_FV(B3,"Employees")} -> 166000 | T3: {=_FV(B3,"Industry")} -> Computers, Phones & Household Electronics | U3: {=_FV(B3,"Market cap",TRUE)} -> 4284890406400 | V3: {=_FV(B3,"Shares outstanding",TRUE)} -> 14687360000
A4: ADBE | B4: #VALUE! | C4: {=_FV(B4,"Last trade time",TRUE)} -> 46182.798 | D4: {=_FV(B4,"Currency")} -> USD | E4: {=_FV(B4,"Price")} -> 238.4 | F4: {=_FV(B4,"Change (%)",TRUE)} -> -0.026899 | G4: {=_FV(B4,"Change")} -> -6.59 | H4: {=_FV(B4,"P/E",TRUE)} -> 13.895 | I4: {=_FV(B4,"Beta")} -> 1.4023 | J4: {=_FV(B4,"52 week high",TRUE)} -> 419.82 | K4: {=_FV(B4,"52 week low",TRUE)} -> 224.13 | L4: {=_FV(B4,"High")} -> 245.25 | M4: {=_FV(B4,"Low")} -> 233.35 | N4: {=_FV(B4,"Open")} -> 242.54 | O4: {=_FV(B4,"Previous close",TRUE)} -> 244.99 | P4: {=_FV(B4,"Volume")} -> 4333195 | Q4: {=_FV(B4,"Volume average",TRUE)} -> 4913632 | R4: {=_FV(B4,"Year incorporated",TRUE)} -> 1997 | S4: {=_FV(B4,"Employees")} -> 31360 | T4: {=_FV(B4,"Industry")} -> Software & IT Services | U4: {=_FV(B4,"Market cap",TRUE)} -> 96361280000 | V4: {=_FV(B4,"Shares outstanding",TRUE)} -> 404200000
A5: AEHR | B5: #VALUE! | C5: {=_FV(B5,"Last trade time",TRUE)} -> 46182.798 | D5: {=_FV(B5,"Currency")} -> USD | E5: {=_FV(B5,"Price")} -> 93.1301 | F5: {=_FV(B5,"Change (%)",TRUE)} -> -0.025632 | G5: {=_FV(B5,"Change")} -> -2.4499 | H5: {=_FV(B5,"P/E",TRUE)} -> 0 | I5: {=_FV(B5,"Beta")} -> 3.1745 | J5: {=_FV(B5,"52 week high",TRUE)} -> 121.8 | K5: {=_FV(B5,"52 week low",TRUE)} -> 10.8875 | L5: {=_FV(B5,"High")} -> 106.52 | M5: {=_FV(B5,"Low")} -> 84.615 | N5: {=_FV(B5,"Open")} -> 99.73 | O5: {=_FV(B5,"Previous close",TRUE)} -> 95.58 | P5: {=_FV(B5,"Volume")} -> 2016667 | Q5: {=_FV(B5,"Volume average",TRUE)} -> 2507789 | R5: {=_FV(B5,"Year incorporated",TRUE)} -> 1977 | S5: {=_FV(B5,"Employees")} -> 136 | T5: {=_FV(B5,"Industry")} -> Semiconductors & Semiconductor Equipment | U5: {=_FV(B5,"Market cap",TRUE)} -> 2929244317 | V5: {=_FV(B5,"Shares outstanding",TRUE)} -> 31453250
A6: AI | B6: #VALUE! | C6: {=_FV(B6,"Last trade time",TRUE)} -> 46182.783 | D6: {=_FV(B6,"Currency")} -> CAD | E6: {=_FV(B6,"Price")} -> 11.77 | F6: {=_FV(B6,"Change (%)",TRUE)} -> 0.007705 | G6: {=_FV(B6,"Change")} -> 0.09 | H6: {=_FV(B6,"P/E",TRUE)} -> 11.185 | I6: {=_FV(B6,"Beta")} -> 0.8377 | J6: {=_FV(B6,"52 week high",TRUE)} -> 12.24 | K6: {=_FV(B6,"52 week low",TRUE)} -> 10.99 | L6: {=_FV(B6,"High")} -> 11.78 | M6: {=_FV(B6,"Low")} -> 11.7 | N6: {=_FV(B6,"Open")} -> 11.73 | O6: {=_FV(B6,"Previous close",TRUE)} -> 11.68 | P6: {=_FV(B6,"Volume")} -> 4100 | Q6: {=_FV(B6,"Volume average",TRUE)} -> 118700 | R6: {=_FV(B6,"Year incorporated",TRUE)} -> 2001 | S6: {=_FV(B6,"Employees")} -> 0 | T6: {=_FV(B6,"Industry")} -> Banking Services | U6: {=_FV(B6,"Market cap",TRUE)} -> 567781151 | V6: {=_FV(B6,"Shares outstanding",TRUE)} -> 48239690
A7: ALAB | B7: #VALUE! | C7: {=_FV(B7,"Last trade time",TRUE)} -> 46182.798 | D7: {=_FV(B7,"Currency")} -> USD | E7: {=_FV(B7,"Price")} -> 337.405 | F7: {=_FV(B7,"Change (%)",TRUE)} -> -0.02577 | G7: {=_FV(B7,"Change")} -> -8.925 | H7: {=_FV(B7,"P/E",TRUE)} -> 227.4538 | I7: {=_FV(B7,"Beta")} -> 2.64 | J7: {=_FV(B7,"52 week high",TRUE)} -> 372.37 | K7: {=_FV(B7,"52 week low",TRUE)} -> 84.78 | L7: {=_FV(B7,"High")} -> 372.11 | M7: {=_FV(B7,"Low")} -> 303 | N7: {=_FV(B7,"Open")} -> 354.01 | O7: {=_FV(B7,"Previous close",TRUE)} -> 346.33 | P7: {=_FV(B7,"Volume")} -> 5688448 | Q7: {=_FV(B7,"Volume average",TRUE)} -> 6259818 | R7: {=_FV(B7,"Year incorporated",TRUE)} -> 2017 | S7: {=_FV(B7,"Employees")} -> 756 | T7: {=_FV(B7,"Industry")} -> Semiconductors & Semiconductor Equipment | U7: {=_FV(B7,"Market cap",TRUE)} -> 57833882499 | V7: {=_FV(B7,"Shares outstanding",TRUE)} -> 171407900
A8: AMBA | B8: #VALUE! | C8: {=_FV(B8,"Last trade time",TRUE)} -> 46182.798 | D8: {=_FV(B8,"Currency")} -> USD | E8: {=_FV(B8,"Price")} -> 65.045 | F8: {=_FV(B8,"Change (%)",TRUE)} -> -0.053478 | G8: {=_FV(B8,"Change")} -> -3.675 | H8: {=_FV(B8,"P/E",TRUE)} -> 0 | I8: {=_FV(B8,"Beta")} -> 2.1395 | J8: {=_FV(B8,"52 week high",TRUE)} -> 96.69 | K8: {=_FV(B8,"52 week low",TRUE)} -> 48.3 | L8: {=_FV(B8,"High")} -> 69.95 | M8: {=_FV(B8,"Low")} -> 61.8 | N8: {=_FV(B8,"Open")} -> 69.78 | O8: {=_FV(B8,"Previous close",TRUE)} -> 68.72 | P8: {=_FV(B8,"Volume")} -> 1235100 | Q8: {=_FV(B8,"Volume average",TRUE)} -> 1647508 | R8: {=_FV(B8,"Year incorporated",TRUE)} -> 2004 | S8: {=_FV(B8,"Employees")} -> 959 | T8: {=_FV(B8,"Industry")} -> Semiconductors & Semiconductor Equipment | U8: {=_FV(B8,"Market cap",TRUE)} -> 2853405768 | V8: {=_FV(B8,"Shares outstanding",TRUE)} -> 43868180
A9: AMD | B9: #VALUE! | C9: {=_FV(B9,"Last trade time",TRUE)} -> 46182.798 | D9: {=_FV(B9,"Currency")} -> USD | E9: {=_FV(B9,"Price")} -> 468.5845 | F9: {=_FV(B9,"Change (%)",TRUE)} -> -0.044349 | G9: {=_FV(B9,"Change")} -> -21.7455 | H9: {=_FV(B9,"P/E",TRUE)} -> 156.2 | I9: {=_FV(B9,"Beta")} -> 2.4927 | J9: {=_FV(B9,"52 week high",TRUE)} -> 546.44 | K9: {=_FV(B9,"52 week low",TRUE)} -> 115.06 | L9: {=_FV(B9,"High")} -> 504.56 | M9: {=_FV(B9,"Low")} -> 437.23 | N9: {=_FV(B9,"Open")} -> 503.79 | O9: {=_FV(B9,"Previous close",TRUE)} -> 490.33 | P9: {=_FV(B9,"Volume")} -> 29555060 | Q9: {=_FV(B9,"Volume average",TRUE)} -> 37988274 | R9: {=_FV(B9,"Year incorporated",TRUE)} -> 1969 | S9: {=_FV(B9,"Employees")} -> 31000 | T9: {=_FV(B9,"Industry")} -> Semiconductors & Semiconductor Equipment | U9: {=_FV(B9,"Market cap",TRUE)} -> 764074354284 | V9: {=_FV(B9,"Shares outstanding",TRUE)} -> 1630601000
A10: AMZN | B10: #VALUE! | C10: {=_FV(B10,"Last trade time",TRUE)} -> 46182.798 | D10: {=_FV(B10,"Currency")} -> USD | E10: {=_FV(B10,"Price")} -> 245.59 | F10: {=_FV(B10,"Change (%)",TRUE)} -> 0.001509 | G10: {=_FV(B10,"Change")} -> 0.37 | H10: {=_FV(B10,"P/E",TRUE)} -> 29.3498 | I10: {=_FV(B10,"Beta")} -> 1.4595 | J10: {=_FV(B10,"52 week high",TRUE)} -> 278.56 | K10: {=_FV(B10,"52 week low",TRUE)} -> 196 | L10: {=_FV(B10,"High")} -> 250.43 | M10: {=_FV(B10,"Low")} -> 240.4 | N10: {=_FV(B10,"Open")} -> 247.68 | O10: {=_FV(B10,"Previous close",TRUE)} -> 245.22 | P10: {=_FV(B10,"Volume")} -> 28749792 | Q10: {=_FV(B10,"Volume average",TRUE)} -> 40455637 | R10: {=_FV(B10,"Year incorporated",TRUE)} -> 1996 | S10: {=_FV(B10,"Employees")} -> 1575000 | T10: {=_FV(B10,"Industry")} -> Diversified Retail | U10: {=_FV(B10,"Market cap",TRUE)} -> 2641838644900 | V10: {=_FV(B10,"Shares outstanding",TRUE)} -> 10757110000
A11: ANET | B11: #VALUE! | C11: {=_FV(B11,"Last trade time",TRUE)} -> 46182.798 | D11: {=_FV(B11,"Currency")} -> USD | E11: {=_FV(B11,"Price")} -> 151.98 | F11: {=_FV(B11,"Change (%)",TRUE)} -> -0.028261 | G11: {=_FV(B11,"Change")} -> -4.42 | H11: {=_FV(B11,"P/E",TRUE)} -> 52.0551 | I11: {=_FV(B11,"Beta")} -> 1.6127 | J11: {=_FV(B11,"52 week high",TRUE)} -> 179.8 | K11: {=_FV(B11,"52 week low",TRUE)} -> 85.58 | L11: {=_FV(B11,"High")} -> 158.99 | M11: {=_FV(B11,"Low")} -> 145.37 | N11: {=_FV(B11,"Open")} -> 157.755 | O11: {=_FV(B11,"Previous close",TRUE)} -> 156.4 | P11: {=_FV(B11,"Volume")} -> 4752998 | Q11: {=_FV(B11,"Volume average",TRUE)} -> 12494259 | R11: {=_FV(B11,"Year incorporated",TRUE)} -> 2011 | S11: {=_FV(B11,"Employees")} -> 5115 | T11: {=_FV(B11,"Industry")} -> Communications & Networking | U11: {=_FV(B11,"Market cap",TRUE)} -> 191373671940 | V11: {=_FV(B11,"Shares outstanding",TRUE)} -> 1259203000
A12: APP | B12: #VALUE! | C12: {=_FV(B12,"Last trade time",TRUE)} -> 46182.798 | D12: {=_FV(B12,"Currency")} -> USD | E12: {=_FV(B12,"Price")} -> 522.94 | F12: {=_FV(B12,"Change (%)",TRUE)} -> -0.072292 | G12: {=_FV(B12,"Change")} -> -40.75 | H12: {=_FV(B12,"P/E",TRUE)} -> 45.4434 | I12: {=_FV(B12,"Beta")} -> 2.4694 | J12: {=_FV(B12,"52 week high",TRUE)} -> 745.61 | K12: {=_FV(B12,"52 week low",TRUE)} -> 320 | L12: {=_FV(B12,"High")} -> 567.66 | M12: {=_FV(B12,"Low")} -> 502.81 | N12: {=_FV(B12,"Open")} -> 556.71 | O12: {=_FV(B12,"Previous close",TRUE)} -> 563.69 | P12: {=_FV(B12,"Volume")} -> 3502141 | Q12: {=_FV(B12,"Volume average",TRUE)} -> 5252653 | R12: {=_FV(B12,"Year incorporated",TRUE)} -> 2011 | S12: {=_FV(B12,"Employees")} -> 898 | T12: {=_FV(B12,"Industry")} -> Software & IT Services | U12: {=_FV(B12,"Market cap",TRUE)} -> 175676463600 | V12: {=_FV(B12,"Shares outstanding",TRUE)} -> 335940000
A13: ARKK | B13: #VALUE! | C13: {=_FV(B13,"Last trade time",TRUE)} -> 46182.798 | D13: {=_FV(B13,"Currency")} -> USD | E13: {=_FV(B13,"Price")} -> 75 | F13: {=_FV(B13,"Change (%)",TRUE)} -> -0.011597 | G13: {=_FV(B13,"Change")} -> -0.88 | H13: {=_FV(B13,"P/E",TRUE)} -> #VALUE! | I13: {=_FV(B13,"Beta")} -> 2.04 | J13: {=_FV(B13,"52 week high",TRUE)} -> 92.65 | K13: {=_FV(B13,"52 week low",TRUE)} -> 60.54 | L13: {=_FV(B13,"High")} -> 77.495 | M13: {=_FV(B13,"Low")} -> 72.1 | N13: {=_FV(B13,"Open")} -> 76.46 | O13: {=_FV(B13,"Previous close",TRUE)} -> 75.88 | P13: {=_FV(B13,"Volume")} -> 9119137 | Q13: {=_FV(B13,"Volume average",TRUE)} -> 7452453 | R13: {=_FV(B13,"Year incorporated",TRUE)} -> #VALUE! | S13: {=_FV(B13,"Employees")} -> #VALUE! | T13: {=_FV(B13,"Industry")} -> #VALUE! | U13: {=_FV(B13,"Market cap",TRUE)} -> 7.2621988e+09 | V13: {=_FV(B13,"Shares outstanding",TRUE)} -> #VALUE!
... A95: ZS | B95: #VALUE! | C95: {=_FV(B95,"Last trade time",TRUE)} -> 46182.798 | D95: {=_FV(B95,"Currency")} -> USD | E95: {=_FV(B95,"Price")} -> 124.7 | F95: {=_FV(B95,"Change (%)",TRUE)} -> -0.035203 | G95: {=_FV(B95,"Change")} -> -4.55 | H95: {=_FV(B95,"P/E",TRUE)} -> 0 | I95: {=_FV(B95,"Beta")} -> 0.9749 | J95: {=_FV(B95,"52 week high",TRUE)} -> 336.99 | K95: {=_FV(B95,"52 week low",TRUE)} -> 114.625 | L95: {=_FV(B95,"High")} -> 130.1449 | M95: {=_FV(B95,"Low")} -> 120.851 | N95: {=_FV(B95,"Open")} -> 128.11 | O95: {=_FV(B95,"Previous close",TRUE)} -> 129.25 | P95: {=_FV(B95,"Volume")} -> 3520353 | Q95: {=_FV(B95,"Volume average",TRUE)} -> 6397211 | R95: {=_FV(B95,"Year incorporated",TRUE)} -> 2007 | S95: {=_FV(B95,"Employees")} -> 7923 | T95: {=_FV(B95,"Industry")} -> Software & IT Services | U95: {=_FV(B95,"Market cap",TRUE)} -> 20165174650 | V95: {=_FV(B95,"Shares outstanding",TRUE)} -> 161709500

Sheet holdings
A1: Symbol | B1: StockName | C1: TradeCurrency | D1: TotalBought | E1: TotalSold | F1: NetPosition | G1: AvgCost | H1: AvgBuyCost | I1: StockPrice | J1: FXRate | K1: ChangePercent | L1: MarketValue | M1: P&L | N1: P&LPercent
A2: META | B2: #VALUE! | C2: =_FV(B2,"Currency") -> USD | D2: 6 | E2: 0 | F2: 6 | G2: 527.97667 | H2: =F2*G2 -> 3167.86 | I2: =_FV(B2,"Price") -> 591.13 | J2: =Config!$C$1 -> 0.7469 | K2: {=_FV(B2,"Change (%)",TRUE)} -> 0.009805 | L2: =F2*I2*J2 -> 2649.09 | M2: =L2-H2 -> -518.77002 | N2: =IF(H2=0,"",M2/H2) -> -0.1637604
A3: HOOD | B3: #VALUE! | C3: =_FV(B3,"Currency") -> USD | D3: 75 | E3: 0 | F3: 75 | G3: 48.637324 | H3: =F3*G3 -> 3647.7993 | I3: =_FV(B3,"Price") -> 83.89 | J3: =Config!$C$1 -> 0.7469 | K3: {=_FV(B3,"Change (%)",TRUE)} -> -0.013523 | L3: =F3*I3*J3 -> 4699.3081 | M3: =L3-H3 -> 1051.5088 | N3: =IF(H3=0,"",M3/H3) -> 0.2882584
A4: NVIDIA | B4: #VALUE! | C4: =_FV(B4,"Currency") -> USD | D4: 18 | E4: 0 | F4: 18 | G4: 129.58 | H4: =F4*G4 -> 2332.44 | I4: =_FV(B4,"Price") -> 206.91 | J4: =Config!$C$1 -> 0.7469 | K4: {=_FV(B4,"Change (%)",TRUE)} -> -0.008292 | L4: =F4*I4*J4 -> 2781.7394 | M4: =L4-H4 -> 449.29942 | N4: =IF(H4=0,"",M4/H4) -> 0.19263065
A5: AMD | B5: #VALUE! | C5: =_FV(B5,"Currency") -> USD | D5: 12 | E5: 0 | F5: 12 | G5: 154.96 | H5: =F5*G5 -> 1859.52 | I5: =_FV(B5,"Price") -> 468.5845 | J5: =Config!$C$1 -> 0.7469 | K5: {=_FV(B5,"Change (%)",TRUE)} -> -0.044349 | L5: =F5*I5*J5 -> 4199.8292 | M5: =L5-H5 -> 2340.3092 | N5: =IF(H5=0,"",M5/H5) -> 1.2585555
A6: CRWV | B6: #VALUE! | C6: =_FV(B6,"Currency") -> USD | D6: 31 | E6: 0 | F6: 31 | G6: 66.906129 | H6: =F6*G6 -> 2074.09 | I6: =_FV(B6,"Price") -> 98.02 | J6: =Config!$C$1 -> 0.7469 | K6: {=_FV(B6,"Change (%)",TRUE)} -> -0.042493 | L6: =F6*I6*J6 -> 2269.5453 | M6: =L6-H6 -> 195.45528 | N6: =IF(H6=0,"",M6/H6) -> 0.094236643
A7: TSLA | B7: #VALUE! | C7: =_FV(B7,"Currency") -> USD | D7: 18 | E7: 0 | F7: 18 | G7: 269.68166 | H7: =F7*G7 -> 4854.2699 | I7: =_FV(B7,"Price") -> 396.98 | J7: =Config!$C$1 -> 0.7469 | K7: {=_FV(B7,"Change (%)",TRUE)} -> -0.02927 | L7: =F7*I7*J7 -> 5337.0785 | M7: =L7-H7 -> 482.80862 | N7: =IF(H7=0,"",M7/H7) -> 0.099460604
A8: LWLG | B8: #VALUE! | C8: =_FV(B8,"Currency") -> USD | D8: 124 | E8: 0 | F8: 124 | G8: 8.816371 | H8: =F8*G8 -> 1093.23 | I8: =_FV(B8,"Price") -> 9.44 | J8: =Config!$C$1 -> 0.7469 | K8: {=_FV(B8,"Change (%)",TRUE)} -> -0.083495 | L8: =F8*I8*J8 -> 874.29126 | M8: =L8-H8 -> -218.93874 | N8: =IF(H8=0,"",M8/H8) -> -0.20026777
A9: POET | B9: #VALUE! | C9: =_FV(B9,"Currency") -> USD | D9: 446 | E9: 0 | F9: 446 | G9: 5.6275115 | H9: =F9*G9 -> 2509.8701 | I9: =_FV(B9,"Price") -> 10.745 | J9: =Config!$C$1 -> 0.7469 | K9: {=_FV(B9,"Change (%)",TRUE)} -> -0.125 | L9: =F9*I9*J9 -> 3579.3465 | M9: =L9-H9 -> 1069.4763 | N9: =IF(H9=0,"",M9/H9) -> 0.42610823
A10: SGE.L | B10: #VALUE! | C10: =_FV(B10,"Currency") -> GBp | D10: 100 | E10: 50 | F10: 50 | G10: 100 | H10: =F10*G10 -> 5000 | I10: =_FV(B10,"Price") -> 851.4 | J10: =Config!$C$1 -> 0.7469 | K10: {=_FV(B10,"Change (%)",TRUE)} -> -0.012526 | L10: =F10*I10*J10 -> 31795.533 | M10: =L10-H10 -> 26795.533 | N10: =IF(H10=0,"",M10/H10) -> 5.3591066

Sheet Config
A1: USD/GBP | B1: #VALUE! | C1: {=_FV(B1,"Price")} -> 0.7469

Sheet market_data
A1: collected_timestamp | B1: date | C1: source | D1: symbol | E1: trade_currency | F1: stock_price | G1: pe_ratio | H1: beta | I1: market_cap | J1: industry
A102: 46161.888 | B102: 46161 | C102: YahooFinance | D102: PATH | E102: USD | F102: 10.55 | G102: 20.288464 | H102: 0.909 | I102: 5490677760 | J102: Software - Infrastructure
A103: 46161.888 | B103: 46161 | C103: YahooFinance | D103: INOD | E103: USD | F103: 88.19 | G103: 78.74107 | H103: 2.403 | I103: 2879876096 | J103: Information Technology Services
A104: 46161.888 | B104: 46161 | C104: YahooFinance | D104: NOW | E104: USD | F104: 101.83 | G104: 60.6131 | H104: 0.819 | I104: 105018097664 | J104: Software - Application
A105: 46161.888 | B105: 46161 | C105: YahooFinance | D105: FIVN | E105: USD | F105: 22.52 | G105: 34.646156 | H105: 1.325 | I105: 1724220928 | J105: Software - Infrastructure
A106: 46161.888 | B106: 46161 | C106: YahooFinance | D106: ADBE | E106: USD | F106: 254.99 | G106: 14.868222 | H106: 1.417 | I106: 103066959872 | J106: Software - Application
A107: 46161.888 | B107: 46161 | C107: YahooFinance | D107: QLYS | E107: USD | F107: 100.09 | G107: 17.969479 | H107: 0.579 | I107: 3524870144 | J107: Software - Infrastructure
A108: 46161.888 | B108: 46161 | C108: YahooFinance | D108: SWKS | E108: USD | F108: 70.35 | G108: 29.312498 | H108: 1.476 | I108: 10581059584 | J108: Semiconductors
A109: 46161.888 | B109: 46161 | C109: YahooFinance | D109: MSFT | E109: USD | F109: 417.42 | G109: 24.890877 | H109: 1.093 | I109: 3100777381888 | J109: Software - Infrastructure
A110: 46161.888 | B110: 46161 | C110: YahooFinance | D110: APP | E110: USD | F110: 476.9 | G110: 41.397568 | H110: 2.366 | I110: 160209551360 | J110: Advertising Agencies
A111: 46161.888 | B111: 46161 | C111: YahooFinance | D111: DDOG | E111: USD | F111: 215.15 | G111: 537.875 | H111: 1.295 | I111: 76584837120 | J111: Software - Application
A112: 46161.888 | B112: 46161 | C112: YahooFinance | D112: ALAB | E112: USD | F112: 244.26 | G112: 163.93288 | H112: 3.363 | I112: 41868099584 | J112: Semiconductors
A113: 46161.888 | B113: 46161 | C113: YahooFinance | D113: SNDK | E113: USD | F113: 1383.29 | G113: 47.162975 | I113: 204851085312 | J113: Computer Hardware
A114: 46161.888 | B114: 46161 | C114: YahooFinance | D114: SCHW | E114: USD | F114: 91.81 | G114: 18.252483 | H114: 0.797 | I114: 159670026240 | J114: Capital Markets
A115: 46161.888 | B115: 46161 | C115: YahooFinance | D115: SGE.L | E115: GBp | F115: 908 | G115: 24.54054 | H115: 0.304 | I115: 8206142464 | J115: Software - Application
A116: 46161.888 | B116: 46161 | C116: YahooFinance | D116: IBM | E116: USD | F116: 222.33 | G116: 19.692648 | H116: 0.581 | I116: 208964698112 | J116: Information Technology Services
A117: 46161.888 | B117: 46161 | C117: YahooFinance | D117: AAPL | E117: USD | F117: 298.97 | G117: 36.23879 | H117: 1.065 | I117: 4391078723584 | J117: Consumer Electronics
A118: 46161.888 | B118: 46161 | C118: YahooFinance | D118: KO | E118: USD | F118: 81.92 | G118: 25.761005 | H118: 0.356 | I118: 352459358208 | J118: Beverages - Non-Alcoholic
A119: 46161.888 | B119: 46161 | C119: YahooFinance | D119: AMBA | E119: USD | F119: 76.69 | H119: 2.164 | I119: 3363737344 | J119: Semiconductor Equipment & Materials
A120: 46161.888 | B120: 46161 | C120: YahooFinance | D120: META | E120: USD | F120: 602.61 | G120: 21.91309 | H120: 1.243 | I120: 1529679183872 | J120: Internet Content & Information
A121: 46161.888 | B121: 46161 | C121: YahooFinance | D121: SOUN | E121: USD | F121: 8.45 | H121: 2.763 | I121: 3656903424 | J121: Software - Application
A122: 46161.888 | B122: 46161 | C122: YahooFinance | D122: ORCL | E122: USD | F122: 181.46 | G122: 32.636692 | H122: 1.544 | I122: 521887350784 | J122: Software - Infrastructure
A123: 46161.888 | B123: 46161 | C123: YahooFinance | D123: GOOG | E123: USD | F123: 384.9 | G123: 29.404125 | H123: 1.267 | I123: 4663234002944 | J123: Internet Content & Information
A124: 46161.888 | B124: 46161 | C124: YahooFinance | D124: AMZN | E124: USD | F124: 259.34 | G124: 30.984468 | H124: 1.468 | I124: 2789748768768 | J124: Internet Retail
A125: 46161.888 | B125: 46161 | C125: YahooFinance | D125: MRVL | E125: USD | F125: 176.27 | G125: 57.416943 | H125: 2.251 | I125: 154333757440 | J125: Semiconductors
A126: 46161.888 | B126: 46161 | C126: YahooFinance | D126: ENVX | E126: USD | F126: 5.53 | H126: 2.231 | I126: 1206388608 | J126: Electrical Equipment & Parts
A127: 46161.888 | B127: 46161 | C127: YahooFinance | D127: TSM | E127: USD | F127: 392.61 | G127: 33.729378 | H127: 1.264 | I127: 2036232486912 | J127: Semiconductors
A128: 46161.888 | B128: 46161 | C128: YahooFinance | D128: TEM | E128: USD | F128: 45.53 | I128: 8175583744 | J128: Health Information Services
A129: 46161.888 | B129: 46161 | C129: YahooFinance | D129: AVGO | E129: USD | F129: 411.07 | G129: 80.13061 | H129: 1.44 | I129: 1946280132608 | J129: Semiconductors
A130: 46161.888 | B130: 46161 | C130: YahooFinance | D130: SKYT | E130: USD | F130: 34.25 | G130: 14.636753 | H130: 3.304 | I130: 1685257600 | J130: Semiconductors
A131: 46161.888 | B131: 46161 | C131: YahooFinance | D131: AI | E131: USD | F131: 8.83 | H131: 1.987 | I131: 1282921472 | J131: Software - Infrastructure
A132: 46161.888 | B132: 46161 | C132: YahooFinance | D132: ANET | E132: USD | F132: 141.58 | G132: 48.65292 | H132: 1.673 | I132: 178273206272 | J132: Computer Hardware
A133: 46161.888 | B133: 46161 | C133: YahooFinance | D133: PLAB | E133: USD | F133: 45.77 | G133: 19.55983 | H133: 1.507 | I133: 2698891776 | J133: Semiconductor Equipment & Materials
A134: 46161.888 | B134: 46161 | C134: YahooFinance | D134: NVDA | E134: USD | F134: 220.61 | G134: 45.11452 | H134: 2.244 | I134: 5343290064896 | J134: Semiconductors
A135: 46161.888 | B135: 46161 | C135: YahooFinance | D135: HOOD | E135: USD | F135: 74.16 | G135: 36.000004 | H135: 2.294 | I135: 66781462528 | J135: Capital Markets
A136: 46161.888 | B136: 46161 | C136: YahooFinance | D136: LPTH | E136: USD | F136: 13.88 | I136: 871516992 | J136: Electronic Components
A137: 46161.888 | B137: 46161 | C137: YahooFinance | D137: AMD | E137: USD | F137: 414.05 | G137: 138.47826 | H137: 2.399 | I137: 675150168064 | J137: Semiconductors
A138: 46161.888 | B138: 46161 | C138: YahooFinance | D138: TSLA | E138: USD | F138: 404.11 | G138: 364.06305 | H138: 1.793 | I138: 1517725417472 | J138: Auto Manufacturers
A139: 46161.888 | B139: 46161 | C139: YahooFinance | D139: ASML | E139: USD | F139: 1459.44 | G139: 48.583218 | H139: 1.373 | I139: 562493915136 | J139: Semiconductor Equipment & Materials
A140: 46161.888 | B140: 46161 | C140: YahooFinance | D140: MU | E140: USD | F140: 698.74 | G140: 32.95943 | H140: 1.919 | I140: 787992870912 | J140: Semiconductors
...

Sheet dd
A1: Field | B1: Meaning | C1: Example
A2: trade_date | B2: Date trade executed | C2: 46161
A3: account | B3: Which broker/account | C3: IBKR
A4: symbol | B4: Stock ticker | C4: AAPL
A5: action | B5: BUY or SELL | C5: BUY
A6: quantity | B6: Number of shares | C6: 10
A7: trade_currency | B7: Currency stock trades in | C7: USD
A8: trade_price | B8: Price PER share in trade currency | C8: 200
A9: fees | B9: Broker commission in trade currency | C9: 1
A10: fx_rate_to_gbp | B10: FX conversion rate at trade time | C10: 0.79
A11: notes | B11: Free text notes | C11: Swing trade

Sheet Notes
A1: Curated AI / Tech / Infrastructure Watchlist
A3: NOT:
A5: random meme stocks
A6: over-diversified noise
A8: You want:
A10: innovation leaders
A11: infrastructure providers
A12: picks-and-shovels companies
A13: market leaders
A14: ecosystem exposure
A16: That creates MUCH better long-term datasets.
A20: STRUCTURE I RECOMMEND
A22: Your watchlist should include:
A24: Category | B24: Purpose
A25: AI Compute | B25: foundational infrastructure
A26: Semiconductors | B26: core AI supply chain
A27: Hyperscalers | B27: AI deployment
A28: Networking | B28: AI bandwidth
A29: Data Platforms | B29: enterprise AI
A30: Cybersecurity | B30: AI-era security
A31: Robotics | B31: physical AI
A32: Quantum | B32: optional future layer
A33: Energy/Grid | B33: AI power demand
A34: Market ETFs | B34: regime context
A36: This creates:
A38: contextual market intelligence
A39: ML feature richness later
A41: VERY important.
A45: MY HIGH-CONVICTION WATCHLIST
A49: AI COMPUTE / LEADERS
A51: Ticker | B51: Company
A52: NVDA | B52: NVIDIA
A53: AMD | B53: AMD
A54: AVGO | B54: Broadcom
A55: TSM | B55: Taiwan Semiconductor
A56: MU | B56: Micron
A57: ARM | B57: ARM Holdings
A59: These are arguably:
A61: the AI industrial backbone.
A65: AI SOFTWARE / PLATFORMS
...

Sheet metrics
A1: Milestone 10 — Step-by-Step Build Plan
A5: Step 10.1 — Build PRICE_HISTORY Sheet
A7: Create sheet:
A9: PRICE_HISTORY
A11: Columns:
A13: A | B13: B | C13: C
A14: Date | B14: Ticker | C14: Close
A16: Example:
A18: Date | B18: Ticker | C18: Close
A19: 46143 | B19: POET | C19: 5.22
A20: 46144 | B20: POET | C20: 5.31
A23: Goal
A25: This becomes:
A27: the source for all indicators
A28: reusable for every stock
A29: future-proof for Python/ML
A33: Step 10.2 — Add Current Price to HOLDINGS
A35: In HOLDINGS add:
A37: Ticker | B37: Shares | C37: Avg Cost | D37: Current Price
A39: For now you can:
A41: enter prices manually
A42: or use STOCKHISTORY / STOCKDATA if Excel supports it
A46: Step 10.3 — Add MA10
A48: Add new column:
A50: | MA10 |
A52: Formula concept:
A54: MA10=last 10 closes10MA_{10}=\frac{\text{last 10 closes}}{10}MA10​=10last 10 closes​
A56: MA10=∑i=110Pi10MA_{10}=\frac{\sum_{i=1}^{10}P_i}{10}MA10​=10∑i=110​Pi​​
A60: Simple Excel Formula
A62: If your last 10 prices are in:
A64: C2:C11
A66: Then:
A68: =AVERAGE(C2:C11) -> #DIV/0!
A72: Goal
A74: Verify:
A76: formula works
A77: updates correctly
A78: no errors
A80: Only then continue.
A84: Step 10.4 — Add MA20 / MA50 / MA200
...

Sheet decision_engineering
A1: I think the BEST next step is:
A3: M12 — Disposal Simulation Engine
A7: Why THIS Is The Highest Leverage Feature
A9: Because now you can answer:
A11: Question | B11: Example
A12: “If I sell 50 NVDA today…” | B12: projected CGT
A13: “Which shares should I sell?” | B13: tax optimisation
A14: “Can I realise gains tax-free?” | B14: allowance planning
A15: “What disposal minimises CGT?” | B15: alpha
A16: “How much unrealised gain exists?” | B16: exposure
A18: This becomes:
A20: decision intelligence
A22: Question | B22: Why
A23: Do the rankings “feel right”? | B23: intuition validation
A24: Are low-tax positions ranking highly? | B24: tax efficiency
A25: Are oversized positions penalised? | B25: concentration
A26: Are older positions preferred? | B26: holding conviction
A28: SELL OPTIMISER
A29: Why The AI Scores Make Sense
A31: Factor | B31: LWLG Outcome
A32: Tax score | B32: 1.0 (excellent to sell)
A33: Risk score | B33: low
A34: Holding score | B34: low
A35: AI score | B35: strong overall sell candidate
A37: Your weighting system is behaving rationally.
A39: Indicator | B39: Why
A40: VIX | B40: market fear
A41: US10Y Treasury | B41: rates environment
A42: DXY | B42: dollar strength
A43: SPY | B43: broad market trend
A44: QQQ | B44: growth/risk sentiment
A45: Gold | B45: risk-off signal
A46: BTC | B46: speculative appetite
